Workbook

Sheet Index
A1: CDSCO HYDERABAD - 45 kWp BALLAST-TYPE ROOFTOP MMS | DESIGN CALCULATION (IS 800:2007 LSD)
B3: Client / EPC | C3: M/s Sai Babuji Projects Pvt Ltd
B4: Design & Engg | C4: M/s JSP Solar Energy
B5: Drawing | C5: AL-001 R0 (10.09.2026, For Information)
B6: Structure | C6: ISA 50x50x5 frame, 10.115 deg tilt, ballast blocks + J-bolts, 82 tables
B7: Codes | C7: IS 875 (Pt 1,3), IS 800:2007 LSD, IS 456:2000 (anchorage), IS 1893 (Pt 1):2016
B8: Revision | C8: R1 - module dead load as UDL on rafters per client comment (see sheet Revision; R0 superseded)
B10: Sheet | C10: Content (calculation flows top to bottom)
B11: Summary | C11: All checks, utilisation, PASS/FAIL, key results
B12: Revision | C12: R1: client comment, response, R0 -> R1 comparison
B13: Inputs | C13: All inputs (yellow) + code tables - CHANGE ONLY HERE
B14: Section | C14: ISA 50x50x5 properties, unsymmetric-bending modulus
B15: Geometry | C15: Bolt-centre frame, positions, constants
... B27: Notes | C27: Observations on drawing, assumptions, exclusions
B29: Colour code
B30: Input (editable)
B31: PASS
B32: FAIL
B34: Overall status | C34: ="Maximum utilisation "&TEXT(MAX(Summary!G19:G52),"0.000")&" | failed checks: "&COUNTIF(Summary!H19:H52,"FAIL")&" | overall: "&Summary!G57 -> Maximum utilisation 0.929 | failed checks: 0 | overall: REVIEW

Sheet Summary
A1: 0 DESIGN SUMMARY - 45 kWp ballast-type rooftop MMS, CDSCO Hyderabad
A2: All cells are live formulas linked to the calculation sheets. Units: N, mm unless stated. PASS = utilisation <= 1.0
B4: KEY RESULTS
B5: Tilt angle | D5: =g_tilt_deg -> 10.115443 | E5: deg
B6: Design wind pressure pd | D6: =w_pd -> 0.90999516 | E6: kN/m2
B7: Uplift force per module (normal) | D7: =w_Nup/1000 -> 2.1274607 | E7: kN
B8: Downward force per module (normal) | D8: =w_Ndn/1000 -> 1.1867492 | E8: kN
B9: Governing ballast criterion | D9: =b_gov -> Sliding (friction)
B10: REQUIRED ballast block length (300 x 250 x L) | D10: =b_L_rnd -> 650 | E10: mm
B11: PROVIDED ballast block length | D11: =block_L -> 650 | E11: mm
B12: Weight of one block | D12: =b_massb -> 119.26606 | E12: kg
B13: Average roof load (ballast + array) | D13: =b_roof -> 1.8893295 | E13: kN/m2
B14: Max J-bolt tension (factored) | D14: =a_T/1000 -> 1.4684666 | E14: kN
B15: REQUIRED M10 J-bolt length | D15: =a_M10_Ltot -> 140 | E15: mm
B16: REQUIRED M16 J-bolt length (BOM = 150) | D16: =a_M16_Ltot -> 150 | E16: mm
A18: # | B18: Check | C18: Clause | D18: Demand | E18: Capacity | F18: Unit | G18: Utilisation | H18: Status
B19: Members
A20: 1 | B20: Vertical member - tension | C20: IS 800 cl 6.2, 6.3 | D20: =mk_vT_d -> 724.50211 | E20: =mk_vT_c -> 87230.091 | F20: N | G20: =mk_vT_ur -> 0.0083056444 | H20: =mk_vT_ok -> PASS
A21: 2 | B21: Vertical member - compression (single-bolt angle strut) | C21: IS 800 cl 7.1.2, 7.5.1.2, Table 12 | D21: =mk_vC_d -> 592.9695 | E21: =mk_vC_c -> 37025.67 | F21: N | G21: =mk_vC_ur -> 0.016015092 | H21: =mk_vC_ok -> PASS
A22: 3 | B22: Inclined member - tension + bending | C22: IS 800 cl 9.3.1 | D22: =mk_iT_d -> 0.11113324 | E22: =mk_iT_c -> 1 | F22: ratio | G22: =mk_iT_ur -> 0.11113324 | H22: =mk_iT_ok -> PASS
A23: 4 | B23: Inclined member - compression + bending | C23: IS 800 cl 9.3.2 | D23: =mk_iC_d -> 0.11556868 | E23: =mk_iC_c -> 1 | F23: ratio | G23: =mk_iC_ur -> 0.11556868 | H23: =mk_iC_ok -> PASS
A24: 5 | B24: Inclined member - shear | C24: IS 800 cl 8.4 | D24: =mk_iV_d -> 718.96607 | E24: =mk_iV_c -> 32803.993 | F24: N | G24: =mk_iV_ur -> 0.02191703 | H24: =mk_iV_ok -> PASS
A25: 6 | B25: Base member - axial + bending at J-bolt sections | C25: IS 800 cl 9.3, 8.2 | D25: =mk_bS_d -> 0.2080202 | E25: =mk_bS_c -> 1 | F25: ratio | G25: =mk_bS_ur -> 0.2080202 | H25: =mk_bS_ok -> PASS
A26: 7 | B26: Base member - axial + bending at mid-span | C26: IS 800 cl 9.3, 8.2 | D26: =mk_bM_d -> 0.094602859 | E26: =mk_bM_c -> 1 | F26: ratio | G26: =mk_bM_ur -> 0.094602859 | H26: =mk_bM_ok -> PASS
A27: 8 | B27: Base member - shear | C27: IS 800 cl 8.4 | D27: =mk_bV_d -> 763.46653 | E27: =mk_bV_c -> 32803.993 | F27: N | G27: =mk_bV_ur -> 0.023273586 | H27: =mk_bV_ok -> PASS
B28: Connections
A29: 9 | B29: M10 bolt, base-vertical (joint A) | C29: IS 800 cl 10.3.3-10.3.6 | D29: =ck_A_d -> 0.047122089 | E29: =ck_A_c -> 1 | F29: ratio | G29: =ck_A_ur -> 0.047122089 | H29: =ck_A_ok -> PASS
A30: 10 | B30: M10 bolt, vertical-inclined (joint B) | C30: IS 800 cl 10.3.3-10.3.6 | D30: =ck_B_d -> 0.047122089 | E30: =ck_B_c -> 1 | F30: ratio | G30: =ck_B_ur -> 0.047122089 | H30: =ck_B_ok -> PASS
A31: 11 | B31: M12 bolt, base-inclined (joint C) | C31: IS 800 cl 10.3.3-10.3.6 | D31: =ck_C_d -> 0.039681299 | E31: =ck_C_c -> 1 | F31: ratio | G31: =ck_C_ur -> 0.039681299 | H31: =ck_C_ok -> PASS
A32: 12 | B32: M8 SS bolt, module-inclined | C32: IS 800 cl 10.3.3-10.3.6 | D32: =ck_M_d -> 0.039821603 | E32: =ck_M_c -> 1 | F32: ratio | G32: =ck_M_ur -> 0.039821603 | H32: =ck_M_ok -> PASS
B33: Ballast stability (per frame)
A34: 13 | B34: Global uplift | C34: IS 800 Table 4 (0.9DL + 1.5WL) | D34: =bk_up_d -> 1570.7934 | E34: =bk_up_c -> 2325.1223 | F34: N | G34: =bk_up_ur -> 0.67557454 | H34: =bk_up_ok -> PASS
A35: 14 | B35: Sliding / horizontal movement - wind uplift case | C35: IS 800 Table 4; friction mu | D35: =bk_sl_d -> 280.23776 | E35: =bk_sl_c -> 301.73155 | F35: N | G35: =bk_sl_ur -> 0.9287652 | H35: =bk_sl_ok -> PASS
A36: 15 | B36: Overturning - wind uplift case | C36: IS 800 Table 4 | D36: =bk_ot_d -> 888727.53 | E36: =bk_ot_c -> 1161631.5 | F36: N.mm | G36: =bk_ot_ur -> 0.76506838 | H36: =bk_ot_ok -> PASS
A37: 16 | B37: Per-block uplift (J-bolt reactions) | C37: IS 800 Table 4 | D37: =bk_bl_d -> 694.333 | E37: =bk_bl_c -> 1053 | F37: N | G37: =bk_bl_ur -> 0.65938556 | H37: =bk_bl_ok -> PASS
A38: 17 | B38: Sliding - downward wind | C38: IS 800 Table 4 | D38: =bk_sd_d -> 156.32342 | E38: =bk_sd_c -> 1900.5722 | F38: N | G38: =bk_sd_ur -> 0.082250716 | H38: =bk_sd_ok -> PASS
A39: 18 | B39: Overturning - downward wind | C39: IS 800 Table 4 | D39: =bk_od_d -> 0 | E39: =bk_od_c -> 1939151.3 | F39: N.mm | G39: =bk_od_ur -> 0 | H39: =bk_od_ok -> PASS
A40: 19 | B40: Sliding - seismic | C40: IS 1893-1:2016; IS 800 Table 4 | D40: =bk_se_d -> 387.52038 | E40: =bk_se_c -> 930.04891 | F40: N | G40: =bk_se_ur -> 0.41666667 | H40: =bk_se_ok -> PASS
A41: 20 | B41: Overturning - seismic | C41: IS 1893-1:2016; IS 800 Table 4 | D41: =bk_oe_d -> 58271.844 | E41: =bk_oe_c -> 1161631.5 | F41: N.mm | G41: =bk_oe_ur -> 0.050163794 | H41: =bk_oe_ok -> PASS
B42: J-bolt anchorage
...

Sheet Revision
A1: REVISION R1 - module dead load applied as UDL on the rafters (client comment)
B3: Client comment
B4: Since no purlins are provided in the proposed MMS arrangement and the PV modules are directly supported by the rafters, the module self-weight shall not be considered as concentrated/point loads at the joints. Revise the STAAD model by applying the module dead load as an appropriate UDL on the supporting rafters based on the actual module dimensions, support arrangement and tributary length. Revise the structural analysis/design and load calculations accordingly.
B6: Response
B7: 1. Module dead load is now a UDL on each rafter over the module contact length: w = (Wm / (L x W)) x (L/2) = Wm / (2 W). Module 2279 x 1134 mm, 29.1 kg -> 0.1105 kN/m2; tributary width per rafter = 1139.5 mm (2 rafters at 1400 c/c, 439.5 mm overhang each side carried by the module); contact length along the rafter = 1134 mm (centred on the 4 module bolts, inside the rafter's physical length). w = 0.1259 kN/m (see sheet Loads, rows l_pm .. l_udl_chk).
B8: 2. Rafter self-weight is also a UDL (previously lumped at the bolts). Seismic mass of module and rafter follows the same UDL.
B9: 3. STAAD: two extra nodes (Pa, Pb) mark the contact zone; UNI GY loads on members 8-11 (module) and 7-12 (rafter). Statics, member checks, connection, deflection and the module-bolt demand rows were revised; analysis rows now carry the UDL zones with an exact zero-shear peak moment.
B10: 4. Module WIND: transferred to the rafter through the 4 M8 module bolts (point loads at the bolts, wind_mode 0 - unchanged from R0). The bounding alternative with wind also applied as a UDL (wind_mode 1) is available at one input cell and reported in the report; both satisfy every check.
B11: 5. Ballast, J-bolt and base-member results are unchanged because the resultant and its line of action are unchanged: only the rafter itself is affected.
B13: Quantity | C13: R0 (point loads at module bolts) | D13: R1 (UDL, live from this workbook) | E13: R1 / R0 | F13: Comment
B14: Module dead load on rafter (N/mm) | C14: 2 x Wm/4 point loads | D14: =l_udl_m -> 0.12586905 | F14: UDL over 1134 mm
B15: Rafter max |M|, strength combinations (N.m) | C15: 28.195359 | D15: =m_iM/1000 -> 58.726616 | E15: =D15/C15 -> 2.0828469 | F15: governs rafter bending; combo C1
B16: Rafter N+M utilisation (tension) cl 9.3.1 | C16: 0.053977024 | D16: =mk_iT_ur -> 0.11113324 | E16: =D16/C16 -> 2.058899 | F16: PASS
B17: Rafter N+M utilisation (compression) | C17: 0.058412709 | D17: =mk_iC_ur -> 0.11556868 | E17: =D17/C17 -> 1.9784852 | F17: PASS
B18: Rafter shear utilisation | C18: 0.021797452 | D18: =mk_iV_ur -> 0.02191703 | E18: =D18/C18 -> 1.0054859
B19: Rafter deflection, service (mm) | C19: 0.20035402 | D19: =MAX(d_inc_S1,d_inc_S2) -> 0.40689742 | E19: =D19/C19 -> 2.0308922 | F19: limit L/180 = 6.48 mm
B20: M8 module-bolt utilisation | C20: 0.038715096 | D20: =ck_M_ur -> 0.039821603 | E20: =D20/C20 -> 1.0285808 | F20: bolt load path unchanged
B21: Max J-bolt tension, factored (N) | C21: 1468.5202 | D21: =a_T -> 1468.4666 | E21: =D21/C21 -> 0.99996346
B22: Reaction J1, combination C2 (N) | C22: -1468.5202 | D22: =Combos!$E$56 -> -1468.4666 | E22: =D22/C22 -> 0.99996346
B23: Reaction J4, combination C2 (N) | C23: -1396.1036 | D23: =Combos!$E$59 -> -1396.1577 | E23: =D23/C23 -> 1.0000388
B24: Required block length, 300x250 section (mm) | C24: 633.41529 | D24: =b_L_req -> 633.41529 | E24: =D24/C24 -> 1 | F24: sliding governs - unchanged
B25: Sliding utilisation, provided 650 mm | C25: 0.9287652 | D25: =bk_sl_ur -> 0.9287652 | E25: =D25/C25 -> 1
B26: Overturning utilisation | C26: 0.76506742 | D26: =bk_ot_ur -> 0.76506838 | E26: =D26/C26 -> 1.0000013
B28: R0 values are static (from the issued R0 calculation, git tag R0); R1 values are live formulas.

Sheet Inputs
A1: 1 INPUTS - all design inputs (yellow = editable)
A2: Every other sheet is linked to these cells by name. Status: V = verified fact, I = inference/assumption (flagged in report).
A4: # | B4: Item | C4: Name | D4: Value | E4: Unit | F4: Formula / clause / basis | G4: Status | H4: Remarks
A5: Geometry - drawing AL-001 R0 (mm)
A6: 1 | B6: Base member length (ISA 50x50x5) | C6: base_len | D6: 1200 | E6: mm | F6: Drawing AL-001 sh.2 | G6: V
A7: 2 | B7: Base: end -> bolt to vertical member (A) | C7: base_end_A | D7: 27.5 | E7: mm | F7: Drawing AL-001 sh.2 | G7: V
A8: 3 | B8: Base: end -> bolt to inclined member (C) | C8: base_end_C | D8: 25 | E8: mm | F8: Drawing AL-001 sh.2 | G8: V
A9: 4 | B9: Vertical member length | C9: vert_len | D9: 249.72 | E9: mm | F9: Drawing AL-001 sh.2 | G9: V
A10: 5 | B10: Vertical: end -> bolt (both ends) | C10: vert_end | D10: 22.5 | E10: mm | F10: Drawing AL-001 sh.2 | G10: V
A11: 6 | B11: Inclined member length | C11: incl_len | D11: 1222.01 | E11: mm | F11: Drawing AL-001 sh.2 | G11: V
A12: 7 | B12: Inclined: end -> bolt at vertical member (B) | C12: incl_end_B | D12: 27.47 | E12: mm | F12: Drawing AL-001 sh.2 | G12: V
A13: 8 | B13: Inclined: end -> bolt at base member (C) | C13: incl_end_C | D13: 28.92 | E13: mm | F13: Drawing AL-001 sh.2 | G13: V
A14: 9 | B14: Inclined: end -> module slot (both ends) | C14: slot_end | D14: 67 | E14: mm | F14: Drawing AL-001 sh.2 | G14: V
A15: 10 | B15: Module slot c/c as drawn (cross-check) | C15: slot_cc_dwg | D15: 1088 | E15: mm | F15: Drawing AL-001 sh.2 | G15: V
A16: 11 | B16: Base: end -> first J-bolt hole (both ends) | C16: J_off | D16: 175 | E16: mm | F16: Drawing AL-001 sh.2 | G16: V
A17: 12 | B17: J-bolt spacing within one block | C17: J_pair | D17: 150 | E17: mm | F17: Drawing AL-001 sh.1/2 | G17: V
... A25: 20 | B25: Module mid-plane offset from inclined-member bolt line | C25: e_mod | D25: 25 | E25: mm | F25: t_leg + t_mod/2 (assumed) | G25: I
A26: Module & layout
A27: 21 | B27: Module length | C27: mod_L | D27: 2279 | E27: mm | F27: 550 Wp mono-PERC datasheets (search) | G27: I
A28: 22 | B28: Module width | C28: mod_W | D28: 1134 | E28: mm | F28: 550 Wp mono-PERC datasheets (search) | G28: I
A29: 23 | B29: Module frame thickness | C29: mod_t | D29: 35 | E29: mm | F29: 550 Wp mono-PERC datasheets (search) | G29: I
A30: 24 | B30: Module weight | C30: mod_kg | D30: 29.1 | E30: kg | F30: Indosol 550 Wp datasheet (search summary, single source) | G30: I
A31: 25 | B31: Frame-to-frame spacing = module hole pitch (long side) | C31: frame_sp | D31: 1400 | E31: mm | F31: Datasheet hole pitch 1400; slot geometry matches | G31: I
A32: 26 | B32: Module wind transfer to rafter: 0 = at the 4 module bolts (point loads); 1 = UDL over module contact length | C32: wind_mode | D32: 0 | E32: 0/1 | F32: Design choice (R1); alt run provided | G32: I
A33: Wind - IS 875 (Part 3)
A34: 27 | B34: Basic wind speed, Hyderabad | C34: Vb | D34: 44 | E34: m/s | F34: IS 875-3 Annex A (search-confirmed) | G34: V
A35: 28 | B35: Risk coefficient, 25-yr life (house value from issued ground-mount jobs) | C35: k1_risk | D35: 0.91 | E35: - | F35: Skill template; IS 875-3 Table 1 | G35: I
A36: 29 | B36: Terrain category (2 conservative; 3 = dense urban) | C36: terrain | D36: 2 | E36: cat | F36: Assumed - conservative | G36: I
A37: 30 | B37: Topography factor | C37: k3_topo | D37: 1 | E37: - | F37: IS 875-3 cl 6.3.3 | G37: I
A38: 31 | B38: Cyclonic importance factor (non-cyclonic) | C38: k4_imp | D38: 1 | E38: - | F38: IS 875-3 cl 6.3.4 | G38: I
A39: 32 | B39: Wind directionality factor | C39: Kd_dir | D39: 0.9 | E39: - | F39: IS 875-3 cl 7.2.1 (search-confirmed) | G39: V
A40: 33 | B40: Area averaging factor (A <= 10 m2) | C40: Ka_area | D40: 1 | E40: - | F40: IS 875-3 cl 7.2.2 (search-confirmed) | G40: V
A41: 34 | B41: Combination factor (net Cp used, so 1.0) | C41: Kc_comb | D41: 1 | E41: - | F41: House practice | G41: I
A42: 35 | B42: Roof level above ground (3-storey bldg, assumed) | C42: z_bldg | D42: 12 | E42: m | F42: Assumed | G42: I
A43: Seismic - IS 1893 (Part 1):2016
A44: 36 | B44: Zone factor, Hyderabad = Zone II | C44: Zf | D44: 0.1 | E44: - | F44: IS 1893-1:2016 Table 3 (recall) | G44: I
A45: 37 | B45: Importance factor | C45: I_imp | D45: 1 | E45: - | F45: Assumed | G45: I
A46: 38 | B46: Sa/g (rigid, T < 0.4 s) | C46: SaG | D46: 2.5 | E46: - | F46: IS 1893-1:2016 cl 6.4.2 (recall) | G46: I
A47: 39 | B47: Component response reduction (ap=1) | C47: Rp | D47: 2.5 | E47: - | F47: ASCE-type form; IS clause not retrievable offline | G47: I
A48: 40 | B48: z/h of attachment (roof level) | C48: zh | D48: 1 | E48: - | F48: Roof-mounted | G48: V
...

Sheet Section
A1: 2 SECTION - ISA 50x50x5 (IS 808)
A2: Properties from exact polygon integration incl. root r1=7 / toe r2=3.5 (calc/section_isa.py); agree with IS 808 catalogue to <1%.
A4: # | B4: Item | C4: Name | D4: Value | E4: Unit | F4: Formula / clause / basis | G4: Status | H4: Remarks
A5: Section properties (heel at origin; horizontal leg along +x, vertical leg along +y)
A6: 1 | B6: Area | C6: sec_A | D6: 480.3 | E6: mm2 | F6: computed - exact polygon integration | G6: I
A7: 2 | B7: Centroid distance from back of each leg | C7: sec_cx | D7: 14.04 | E7: mm | F7: computed - exact polygon integration | G7: I
A8: 3 | B8: Ixx (axis // horizontal leg) | C8: sec_Ixx | D8: 109643 | E8: mm4 | F8: computed - exact polygon integration | G8: I
A9: 4 | B9: Iyy (axis // vertical leg) | C9: sec_Iyy | D9: 109643 | E9: mm4 | F9: computed - exact polygon integration | G9: I
A10: 5 | B10: Product of inertia Ixy | C10: sec_Ixy | D10: -64173 | E10: mm4 | F10: computed - exact polygon integration | G10: I
A11: 6 | B11: Leg length | C11: sec_b | D11: 50 | E11: mm | F11: computed - exact polygon integration | G11: I
A12: 7 | B12: Thickness | C12: sec_t | D12: 5 | E12: mm | F12: computed - exact polygon integration | G12: I
A13: 8 | B13: Root radius | C13: sec_r1 | D13: 7 | E13: mm | F13: computed - exact polygon integration | G13: I
A14: 9 | B14: Toe radius | C14: sec_r2 | D14: 3.5 | E14: mm | F14: computed - exact polygon integration | G14: I
A15: Derived
A16: 10 | B16: Iuu (major principal) | C16: sec_Iuu | D16: =(sec_Ixx+sec_Iyy)/2+SQRT(((sec_Ixx-sec_Iyy)/2)^2+sec_Ixy^2) -> 173816 | E16: mm4 | F16: Mohr's circle
A17: 11 | B17: Ivv (minor principal) | C17: sec_Ivv | D17: =(sec_Ixx+sec_Iyy)/2-SQRT(((sec_Ixx-sec_Iyy)/2)^2+sec_Ixy^2) -> 45470 | E17: mm4 | F17: Mohr's circle
A18: 12 | B18: ruu | C18: sec_ruu | D18: =SQRT(sec_Iuu/sec_A) -> 19.023419 | E18: mm
A19: 13 | B19: rvv (min radius of gyration) | C19: sec_rvv | D19: =SQRT(sec_Ivv/sec_A) -> 9.7298509 | E19: mm
A20: 14 | B20: Mass per metre (gamma_s=78.5 kN/m3) | C20: sec_mass | D20: =sec_A*0.000001*gam_s/gacc*1000 -> 3.8433792 | E20: kg/m | F20: catalogue 3.77-3.8
A21: 15 | B21: D = Ixx*Iyy - Ixy^2 | C21: sec_D | D21: =sec_Ixx*sec_Iyy-sec_Ixy^2 -> 7903413520 | E21: mm8
A22: 16 | B22: I_eff: in-plane stiffness, section free to deflect sideways | C22: sec_Ieff | D22: =sec_D/sec_Iyy -> 72083.156 | E22: mm4 | F22: angle loaded in plane of legs -> oblique deflection | H22: Used for deflections and STAAD IZ
A23: Elastic modulus for in-plane bending (unsymmetric bending) - stress/unit M = (Iyy*y - Ixy*x)/D at each vertex
B24: vertex | C24: x (mm) | D24: y (mm) | E24: x-cx | F24: y-cy | G24: s=sigma/M gross | H24: Z=1/|s|
B25: heel | C25: =0 -> 0 | D25: =0 -> 0 | E25: =C25-sec_cx -> -14.04 | F25: =D25-sec_cx -> -14.04 | G25: =(sec_Iyy*F25-sec_Ixy*E25)/sec_D -> -0.00030877502 | H25: =1/ABS(G25) -> 3238.604 | I25: =(sec_Iyy_n*F25-sec_Ixy_n*E25)/sec_D_n -> -0.00030552698 | J25: =1/ABS(I25) -> 3273.0334
B26: toe-h bottom | C26: =sec_b -> 50 | D26: =0 -> 0 | E26: =C26-sec_cx -> 35.96 | F26: =D26-sec_cx -> -14.04 | G26: =(sec_Iyy*F26-sec_Ixy*E26)/sec_D -> 9.720779e-05 | H26: =1/ABS(G26) -> 10287.241 | I26: =(sec_Iyy_n*F26-sec_Ixy_n*E26)/sec_D_n -> 7.4972221e-05 | J26: =1/ABS(I26) -> 13338.274
B27: toe-h top | C27: =sec_b -> 50 | D27: =sec_t -> 5 | E27: =C27-sec_cx -> 35.96 | F27: =D27-sec_cx -> -9.04 | G27: =(sec_Iyy*F27-sec_Ixy*E27)/sec_D -> 0.00016657212 | H27: =1/ABS(G27) -> 6003.4055 | I27: =(sec_Iyy_n*F27-sec_Ixy_n*E27)/sec_D_n -> 0.00014572821 | J27: =1/ABS(I27) -> 6862.0896
B28: inner corner | C28: =sec_t -> 5 | D28: =sec_t -> 5 | E28: =C28-sec_cx -> -9.04 | F28: =D28-sec_cx -> -9.04 | G28: =(sec_Iyy*F28-sec_Ixy*E28)/sec_D -> -0.0001988124 | H28: =1/ABS(G28) -> 5029.8673 | I28: =(sec_Iyy_n*F28-sec_Ixy_n*E28)/sec_D_n -> -0.00019672108 | J28: =1/ABS(I28) -> 5083.3394
B29: toe-v inner | C29: =sec_t -> 5 | D29: =sec_b -> 50 | E29: =C29-sec_cx -> -9.04 | F29: =D29-sec_cx -> 35.96 | G29: =(sec_Iyy*F29-sec_Ixy*E29)/sec_D -> 0.00042546658 | H29: =1/ABS(G29) -> 2350.3608 | I29: =(sec_Iyy_n*F29-sec_Ixy_n*E29)/sec_D_n -> 0.00044008279 | J29: =1/ABS(I29) -> 2272.2997
B30: toe-v outer | C30: =0 -> 0 | D30: =sec_b -> 50 | E30: =C30-sec_cx -> -14.04 | F30: =D30-sec_cx -> 35.96 | G30: =(sec_Iyy*F30-sec_Ixy*E30)/sec_D -> 0.0003848683 | H30: =1/ABS(G30) -> 2598.2914 | I30: =(sec_Iyy_n*F30-sec_Ixy_n*E30)/sec_D_n -> 0.00040203287 | J30: =1/ABS(I30) -> 2487.3588
A31: 17 | B31: Z_eff gross = MIN(Z) | C31: sec_Zg | D31: =MIN(H25:H30) -> 2350.3608 | E31: mm3 | F31: critical fibre over all vertices, either moment sign
A32: Net section at J-bolt hole (hole in horizontal leg; centroid shift neglected)
A33: 18 | B33: Hole area = d0_J * t | C33: sec_Ah | D33: =d0_J*sec_t -> 90 | E33: mm2
A34: 19 | B34: Hole centre x from centroid | C34: sec_xh | D34: =J_gauge-sec_cx -> 13.46 | E34: mm
A35: 20 | B35: Hole centre y from centroid | C35: sec_yh | D35: =sec_t/2-sec_cx -> -11.54 | E35: mm
A36: 21 | B36: Ixx net | C36: sec_Ixx_n | D36: =sec_Ixx-sec_Ah*sec_yh^2 -> 97657.556 | E36: mm4
A37: 22 | B37: Iyy net | C37: sec_Iyy_n | D37: =sec_Iyy-sec_Ah*sec_xh^2 -> 93337.556 | E37: mm4
A38: 23 | B38: Ixy net | C38: sec_Ixy_n | D38: =sec_Ixy-sec_Ah*sec_xh*sec_yh -> -50193.444 | E38: mm4
A39: 24 | B39: D net | C39: sec_D_n | D39: =sec_Ixx_n*sec_Iyy_n-sec_Ixy_n^2 -> 6.5957358e+09 | E39: mm8
A40: 25 | B40: Z_eff net (at J-bolt sections) = MIN(Z net) | C40: sec_Zn | D40: =MIN(J25:J30) -> 2272.2997 | E40: mm3

Sheet Geometry
A1: 3 GEOMETRY - bolt-centre frame from drawing AL-001 R0
A2: Origin at joint A (base-vertical bolt), x along base, y up from ROOF surface. All STAAD nodes derive from here.
A4: # | B4: Item | C4: Name | D4: Value | E4: Unit | F4: Formula / clause / basis | G4: Status | H4: Remarks
A5: Frame triangle A-B-C (bolt centres)
A6: 1 | B6: A-C: base bolt c/c | C6: g_AC | D6: =base_len-base_end_A-base_end_C -> 1147.5 | E6: mm | F6: 1200-27.5-25 | G6: V
A7: 2 | B7: A-B: vertical member bolt c/c | C7: g_AB | D7: =vert_len-2*vert_end -> 204.72 | E7: mm | F7: 249.72-2*22.5 | G7: V
A8: 3 | B8: B-C: inclined member bolt c/c AS DRAWN | C8: g_BCdwg | D8: =incl_len-incl_end_B-incl_end_C -> 1165.62 | E8: mm | F8: 1222.01-27.47-28.92 | G8: V
A9: 4 | B9: B-C working length = hypot(AC, AB) | C9: g_BC | D9: =SQRT(g_AC^2+g_AB^2) -> 1165.6185 | E9: mm | F9: triangle closes exactly (R1: removes 1.3e-6 rounding inconsistency) | G9: V
A10: 5 | B10: Closure check working - drawn B-C (must be ~0) | C10: g_closure | D10: =g_BC-g_BCdwg -> -0.0014824738 | E10: mm | F10: drawn dims close the triangle to 0.002 mm | G10: V
A11: 6 | B11: Tilt angle | C11: g_tilt | D11: =ATAN(g_AB/g_AC) -> 0.17654779 | E11: rad | F11: atan(AB/AC) | G11: V
A12: 7 | B12: Tilt angle | C12: g_tilt_deg | D12: =DEGREES(g_tilt) -> 10.115443 | E12: deg | F12: NOT atan(250/1200)=11.77 (ignores hole offsets) | G12: V
A13: 8 | B13: cos(tilt) | C13: g_cos | D13: =COS(g_tilt) -> 0.98445588 | E13: -
A14: 9 | B14: sin(tilt) | C14: g_sin | D14: =SIN(g_tilt) -> 0.17563208 | E14: -
A15: Positions along base member (x from A)
A16: 10 | B16: J-bolt 1 | C16: g_J1 | D16: =J_off-base_end_A -> 147.5 | E16: mm | F16: 175-27.5 | G16: V
A17: 11 | B17: J-bolt 2 | C17: g_J2 | D17: =g_J1+J_pair -> 297.5 | E17: mm | G17: V
A18: 12 | B18: J-bolt 3 | C18: g_J3 | D18: =g_J2+J_mid -> 847.5 | E18: mm | G18: V
A19: 13 | B19: J-bolt 4 | C19: g_J4 | D19: =g_J3+J_pair -> 997.5 | E19: mm | G19: V
A20: 14 | B20: Check: drawing symmetric 175+150+550+150+175 = base length | C20: g_Jchk | D20: =2*J_off+2*J_pair+J_mid-base_len -> 0 | E20: mm | F20: must be 0 | G20: V
A21: 15 | B21: Overhang A to J1 | C21: g_a1 | D21: =g_J1 -> 147.5 | E21: mm
A22: 16 | B22: Overhang J4 to C | C22: g_c2 | D22: =g_AC-g_J4 -> 150 | E22: mm
A23: 17 | B23: Span J1-J2 | C23: g_L1 | D23: =J_pair -> 150 | E23: mm
A24: 18 | B24: Span J2-J3 | C24: g_L2 | D24: =J_mid -> 550 | E24: mm
A25: 19 | B25: Span J3-J4 | C25: g_L3 | D25: =J_pair -> 150 | E25: mm
A26: 20 | B26: Block 1 centre | C26: g_xb1 | D26: =(g_J1+g_J2)/2 -> 222.5 | E26: mm
A27: 21 | B27: Block 2 centre | C27: g_xb2 | D27: =(g_J3+g_J4)/2 -> 922.5 | E27: mm | F27: c/c = 700 as drawn
A28: 22 | B28: Right toe of block 2 (overturning pivot, uplift) | C28: g_xpr | D28: =g_xb2+block_w/2 -> 1072.5 | E28: mm
A29: 23 | B29: Left toe of block 1 (pivot, downward wind) | C29: g_xpl | D29: =g_xb1-block_w/2 -> 72.5 | E29: mm
A30: Heights (y from roof surface) and module load points
A31: 24 | B31: Bolt line above roof = block height + gauge | C31: g_yA | D31: =block_h+bolt_h -> 277.5 | E31: mm | G31: I
A32: 25 | B32: Node B height | C32: g_yB | D32: =g_yA+g_AB -> 482.22 | E32: mm
A33: 26 | B33: Slot 1 distance from B along member | C33: g_s1 | D33: =slot_end-incl_end_B -> 39.53 | E33: mm | F33: 67-27.47 | G33: V
A34: 27 | B34: Slot 2 distance from C along member | C34: g_s2c | D34: =slot_end-incl_end_C -> 38.08 | E34: mm | F34: 67-28.92 | G34: V
A35: 28 | B35: Slot 2 distance from B along member | C35: g_s2 | D35: =g_BC-g_s2c -> 1127.5385 | E35: mm
A36: 29 | B36: Slot c/c (computed) | C36: g_slot_cc | D36: =g_s2-g_s1 -> 1088.0085 | E36: mm
A37: 30 | B37: Check vs drawn 1088 | C37: g_slot_chk | D37: =g_slot_cc-slot_cc_dwg -> 0.0085175262 | E37: mm | F37: 0.01 rounding | G37: V
A38: 31 | B38: S1 x | C38: g_S1x | D38: =g_s1*g_cos -> 38.915541 | E38: mm
A39: 32 | B39: S1 y | C39: g_S1y | D39: =g_yB-g_s1*g_sin -> 475.27726 | E39: mm
A40: 33 | B40: S2 x | C40: g_S2x | D40: =g_s2*g_cos -> 1110.0119 | E40: mm
A41: 34 | B41: S2 y | C41: g_S2y | D41: =g_yB-g_s2*g_sin -> 284.18807 | E41: mm
...

Sheet Wind
A1: 4 WIND LOAD - IS 875 (Part 3)
A2: Vz = Vb k1 k2 k3 k4 ; pz = 0.6 Vz^2 ; pd = Kd Ka Kc pz ; F = Cp pd A (net Cp, Table 7 mono-slope free roof)
A4: # | B4: Item | C4: Name | D4: Value | E4: Unit | F4: Formula / clause / basis | G4: Status | H4: Remarks
A5: Design wind speed
A6: 1 | B6: Height of panel top above ground | C6: w_z | D6: =z_bldg+(g_yB+e_mod+mod_t/2)/1000 -> 12.52472 | E6: m | F6: roof level + panel top | G6: I
A7: 2 | B7: k2 terrain/height factor (interpolated, Table 2) | C7: w_k2 | D7: =INDEX(K2_tab,MIN(MATCH(MIN(MAX(w_z,10),20),K2_h,1),2),terrain-1)+(MIN(MAX(w_z,10),20)-INDEX(K2_h,MIN(MATCH(MIN(MAX(w_z,10),20),K2_h,1),2)))/(INDEX(K2_h,MIN(MATCH(MIN(MAX(w_z,10),20),K2_h,1),2)+1)-INDEX(K2_h,MIN(MATCH(MIN(MAX(w_z,10),20),K2_h,1),2)))*(INDEX(K2_tab,MIN(MATCH(MIN(MAX(w_z,10),20),K2_h,1),2)+1,terrain-1)-INDEX(K2_tab,MIN(MATCH(MIN(MAX(w_z,10),20),K2_h,1),2),terrain-1)) -> 1.0252472 | E7: - | F7: IS 875-3 cl 6.3.2, Table 2 (Cat 2 or 3) | G7: I
A8: 3 | B8: Design wind speed Vz | C8: w_Vz | D8: =Vb*k1_risk*w_k2*k3_topo*k4_imp -> 41.050898 | E8: m/s | F8: IS 875-3 cl 6.3 | G8: V
A9: 4 | B9: Wind pressure pz = 0.6 Vz^2 | C9: w_pz | D9: =0.6*w_Vz^2/1000 -> 1.0111057 | E9: kN/m2 | F9: IS 875-3 cl 7.2 | G9: V
A10: 5 | B10: Height<10 m reduction factor | C10: w_hf | D10: =IF(w_z<10,0.8,1) -> 1 | E10: - | F10: house rule; not applicable at roof level | G10: I
A11: 6 | B11: Design pressure pd = Kd Ka Kc pz (>= 0.7 pz) | C11: w_pd | D11: =MAX(Kd_dir*Ka_area*Kc_comb*w_pz*w_hf,0.7*w_pz) -> 0.90999516 | E11: kN/m2 | F11: IS 875-3 cl 7.2.1 | G11: V
A12: Pressure coefficients - Table 7, interpolated at tilt
A13: 7 | B13: Cp max (downward pressure) | C13: w_cp_dn | D13: =INDEX(T7_dn,MATCH(g_tilt_deg,T7_ang,1))+(g_tilt_deg-INDEX(T7_ang,MATCH(g_tilt_deg,T7_ang,1)))/(INDEX(T7_ang,MATCH(g_tilt_deg,T7_ang,1)+1)-INDEX(T7_ang,MATCH(g_tilt_deg,T7_ang,1)))*(INDEX(T7_dn,MATCH(g_tilt_deg,T7_ang,1)+1)-INDEX(T7_dn,MATCH(g_tilt_deg,T7_ang,1))) -> 0.50461772 | E13: - | F13: IS 875-3 Table 7 (house-verified values) | G13: V
A14: 8 | B14: Cp min (uplift suction) | C14: w_cp_up | D14: =INDEX(T7_up,MATCH(g_tilt_deg,T7_ang,1))+(g_tilt_deg-INDEX(T7_ang,MATCH(g_tilt_deg,T7_ang,1)))/(INDEX(T7_ang,MATCH(g_tilt_deg,T7_ang,1)+1)-INDEX(T7_ang,MATCH(g_tilt_deg,T7_ang,1)))*(INDEX(T7_up,MATCH(g_tilt_deg,T7_ang,1)+1)-INDEX(T7_up,MATCH(g_tilt_deg,T7_ang,1))) -> -0.90461772 | E14: - | F14: IS 875-3 Table 7 | G14: V
A15: Forces (normal to module)
A16: 9 | B16: Module area | C16: w_Amod | D16: =mod_L*mod_W/1000000 -> 2.584386 | E16: m2
A17: 10 | B17: Uplift force per module | C17: w_Nup | D17: =ABS(w_cp_up)*w_pd*w_Amod*1000 -> 2127.4607 | E17: N | F17: Cp pd A
A18: 11 | B18: Downward force per module | C18: w_Ndn | D18: =w_cp_dn*w_pd*w_Amod*1000 -> 1186.7492 | E18: N
A19: 12 | B19: Uplift per module bolt (÷4) | C19: w_Fn_u | D19: =w_Nup/4 -> 531.86518 | E19: N | F19: 4 bolts, equal share | G19: I
A20: 13 | B20: Downward per module bolt (÷4) | C20: w_Fn_d | D20: =w_Ndn/4 -> 296.68731 | E20: N | G20: I

Sheet Loads
A1: 5 DEAD & SEISMIC LOADS
A2: Loads per FRAME (2 frames per module). Member self-weights lumped as nodal loads (same in STAAD).
A4: # | B4: Item | C4: Name | D4: Value | E4: Unit | F4: Formula / clause / basis | G4: Status | H4: Remarks
A5: Dead load - IS 875 (Part 1)
A6: 1 | B6: Steel self-weight per mm of ISA 50x50x5 | C6: l_ws | D6: =sec_A*0.000001*gam_s -> 0.03770355 | E6: N/mm | F6: A * gamma_s (1 kN/m = 1 N/mm) | G6: V
A7: 2 | B7: Module weight | C7: l_Wm | D7: =mod_kg*gacc -> 285.471 | E7: N | G7: I
A8: 3 | B8: Base member weight | C8: l_Wbase | D8: =l_ws*base_len -> 45.24426 | E8: N
A9: 4 | B9: Vertical member weight | C9: l_Wv | D9: =l_ws*vert_len -> 9.4153305 | E9: N
A10: 5 | B10: Inclined member weight | C10: l_Winc | D10: =l_ws*incl_len -> 46.074115 | E10: N
A11: 6 | B11: Base stub weight beyond A | C11: l_stubA | D11: =l_ws*base_end_A -> 1.0368476 | E11: N | F11: lumped at A
A12: 7 | B12: Base stub weight beyond C | C12: l_stubC | D12: =l_ws*base_end_C -> 0.94258875 | E12: N | F12: lumped at C
A13: 8 | B13: Dead load per slot = Wm/4 + Winc/2 | C13: l_slotdl | D13: =l_Wm/4+l_Winc/2 -> 94.404808 | E13: N | F13: module 4 bolts; incl. member split to 2 slots
A14: R1 Module dead load as UDL on the rafter - tributary derivation (client comment: no purlins, module bears directly on rafters)
A15: 9 | B15: Module weight per unit area = Wm / (L x W) | C15: l_pm | D15: =l_Wm/(mod_L*mod_W) -> 0.00011045989 | E15: N/mm2 | F15: uniform over the module
A16: 10 | B16: same, in kN/m2 | C16: l_pm_kN | D16: =l_pm*1000 -> 0.11045989 | E16: kN/m2
A17: 11 | B17: Tributary width per rafter = L/2 | C17: l_trib | D17: =mod_L/2 -> 1139.5 | E17: mm | F17: 2 rafters at 1400 c/c, symmetric overhangs (g_mod_ovh each side) -> each rafter takes half the module | G17: I
A18: 12 | B18: Module UDL on one rafter = pm x tributary width | C18: l_udl_m | D18: =l_pm*l_trib -> 0.12586905 | E18: N/mm | F18: numerically = kN/m; per mm of rafter length, vertical | G18: I
A19: 13 | B19: Check: UDL x contact length - Wm/2 (must be 0) | C19: l_udl_chk | D19: =l_udl_m*g_Lm-l_Wm/2 -> 0 | E19: N | F19: load conserved
A20: 14 | B20: Rafter self-weight UDL = Winc / B-C (stubs spread) | C20: l_udl_r | D20: =l_Winc/g_BC -> 0.039527611 | E20: N/mm | F20: weight conserved
A21: 15 | B21: Wind uplift as UDL over contact length (wind_mode = 1 only) | C21: l_qu | D21: =(w_Nup/2)/g_Lm -> 0.93803383 | E21: N/mm | F21: normal to module; = N per frame / contact length
A22: 16 | B22: Wind downward as UDL over contact length (wind_mode = 1 only) | C22: l_qd | D22: =(w_Ndn/2)/g_Lm -> 0.52325804 | E22: N/mm
A23: Seismic - IS 1893 (Part 1):2016 (horizontal only)
A24: 17 | B24: Ah = (Z/2) I (Sa/g)(1+z/h)/Rp | C24: l_Ah | D24: =Zf/2*I_imp*SaG*(1+zh)/Rp -> 0.1 | E24: - | F24: component at roof level; clause text not retrievable offline | G24: I | H24: Sensitivity: Rp=1 gives Ah=0.25

Sheet Analysis
A1: 6 FRAME ANALYSIS - closed-form statics per load case (one frame)
A2: Same model as STAAD (pinned single-bolt joints, base member continuous on 4 J-bolt supports). Verified against an independent matrix solver to 1e-11.
A4: # | B4: Quantity | C4: Key | D4: DL dead | E4: WL uplift | F4: WL downward | G4: EQ +x | H4: Unit | I4: Basis
B5: Applied loads per frame - module bolts, module UDL zone, rafter UDL, direct loads at A and C
A6: 1 | B6: Point load per module bolt, Fx (x right +) | C6: Fx_s | D6: =0 -> 0 | E6: =IF(wind_mode=0,w_Fn_u*g_sin,0) -> 93.412586 | F6: =IF(wind_mode=0,-w_Fn_d*g_sin,0) -> -52.107808 | G6: =0 -> 0 | H6: N | I6: wind_mode 0: wind through the 4 module bolts
A7: 2 | B7: Point load per module bolt, Fy (y up +) | C7: Fy_s | D7: =0 -> 0 | E7: =IF(wind_mode=0,w_Fn_u*g_cos,0) -> 523.59781 | F7: =IF(wind_mode=0,-w_Fn_d*g_cos,0) -> -292.07557 | G7: =0 -> 0 | H7: N | I7: R1: module DEAD load is NOT a point load any more
A8: 3 | B8: Module UDL on rafter over contact length, x-component | C8: qmx | D8: =0 -> 0 | E8: =IF(wind_mode=1,l_qu*g_sin,0) -> 0 | F8: =IF(wind_mode=1,-l_qd*g_sin,0) -> 0 | G8: =l_Ah*l_udl_m -> 0.012586905 | H8: N/mm | I8: per mm of rafter length, global x
A9: 4 | B9: Module UDL on rafter over contact length, y-component | C9: qmy | D9: =-l_udl_m -> -0.12586905 | E9: =IF(wind_mode=1,l_qu*g_cos,0) -> 0 | F9: =IF(wind_mode=1,-l_qd*g_cos,0) -> 0 | G9: =0 -> 0 | H9: N/mm | I9: DL: module weight x tributary width / contact length
A10: 5 | B10: Rafter self-weight / seismic UDL over full B-C, x | C10: qrx | D10: =0 -> 0 | E10: =0 -> 0 | F10: =0 -> 0 | G10: =l_Ah*l_udl_r -> 0.0039527611 | H10: N/mm
A11: 6 | B11: Rafter self-weight UDL over full B-C, y | C11: qry | D11: =-l_udl_r -> -0.039527611 | E11: =0 -> 0 | F11: =0 -> 0 | G11: =0 -> 0 | H11: N/mm
A12: 7 | B12: Direct horizontal load at A | C12: FxA | D12: =0 -> 0 | E12: =0 -> 0 | F12: =0 -> 0 | G12: =l_Ah*(l_Wv+l_stubA+0.5*l_ws*g_AC) -> 3.208459 | H12: N | I12: EQ on vertical+base masses
A13: 8 | B13: Direct horizontal load at C | C13: FxC | D13: =0 -> 0 | E13: =0 -> 0 | F13: =0 -> 0 | G13: =l_Ah*(l_stubC+0.5*l_ws*g_AC) -> 2.2575001 | H13: N
A14: 9 | B14: Direct downward load at A (vert. member + stub) | C14: dAy | D14: =l_Wv+l_stubA -> 10.452178 | E14: =0 -> 0 | F14: =0 -> 0 | G14: =0 -> 0 | H14: N
A15: 10 | B15: Direct downward load at C (stub) | C15: dCy | D15: =l_stubC -> 0.94258875 | E15: =0 -> 0 | F15: =0 -> 0 | G15: =0 -> 0 | H15: N
A16: 11 | B16: UDL on base member (down +) | C16: wb | D16: =l_ws -> 0.03770355 | E16: =0 -> 0 | F16: =0 -> 0 | G16: =0 -> 0 | H16: N/mm | I16: self-weight
A17: 12 | B17: Module-bolt force per bolt, normal to rafter (up/out +) | C17: Fnb | D17: =-(l_Wm/4)*g_cos -> -70.258401 | E17: =w_Fn_u -> 531.86518 | F17: =-w_Fn_d -> -296.68731 | G17: =l_Ah*(l_Wm/4)*g_sin -> 1.2534466 | H17: N | I17: connection load path: 4 M8 bolts carry the module
A18: 13 | B18: Module-bolt force per bolt, along rafter (B->C +) | C18: Ftb | D18: =(l_Wm/4)*g_sin -> 12.534466 | E18: =0 -> 0 | F18: =0 -> 0 | G18: =l_Ah*(l_Wm/4)*g_cos -> 7.0258401 | H18: N | I18: used for M8 bolt shear
B19: Step 1 - rafter B-C (pin at C; vertical member = 2-force member). Load items: 2 module-bolt points + module UDL + rafter UDL
A20: 14 | B20: Moment about C of module-bolt point loads | C20: msum_p | D20: =(g_S1x-g_AC)*D7-(g_S1y-g_yA)*D6+(g_S2x-g_AC)*D7-(g_S2y-g_yA)*D6 -> 0 | E20: =(g_S1x-g_AC)*E7-(g_S1y-g_yA)*E6+(g_S2x-g_AC)*E7-(g_S2y-g_yA)*E6 -> -619180.7 | F20: =(g_S1x-g_AC)*F7-(g_S1y-g_yA)*F6+(g_S2x-g_AC)*F7-(g_S2y-g_yA)*F6 -> 345394.03 | G20: =(g_S1x-g_AC)*G7-(g_S1y-g_yA)*G6+(g_S2x-g_AC)*G7-(g_S2y-g_yA)*G6 -> 0 | H20: N.mm | I20: M_C = sum[(x-xC)Fy - (y-yC)Fx]
A21: 15 | B21: Moment about C of module UDL resultant (at module centre) | C21: msum_m | D21: =(g_sc*g_cos-g_AC)*D9*g_Lm-(g_yB-g_sc*g_sin-g_yA)*D8*g_Lm -> 81792.618 | E21: =(g_sc*g_cos-g_AC)*E9*g_Lm-(g_yB-g_sc*g_sin-g_yA)*E8*g_Lm -> 0 | F21: =(g_sc*g_cos-g_AC)*F9*g_Lm-(g_yB-g_sc*g_sin-g_yA)*F8*g_Lm -> 0 | G21: =(g_sc*g_cos-g_AC)*G9*g_Lm-(g_yB-g_sc*g_sin-g_yA)*G8*g_Lm -> -1459.2231 | H21: N.mm | I21: resultant q x contact length
A22: 16 | B22: Moment about C of rafter UDL resultant (at mid B-C) | C22: msum_r | D22: =(g_BC/2*g_cos-g_AC)*D11*g_BC-(g_yB-g_BC/2*g_sin-g_yA)*D10*g_BC -> 26435.024 | E22: =(g_BC/2*g_cos-g_AC)*E11*g_BC-(g_yB-g_BC/2*g_sin-g_yA)*E10*g_BC -> 0 | F22: =(g_BC/2*g_cos-g_AC)*F11*g_BC-(g_yB-g_BC/2*g_sin-g_yA)*F10*g_BC -> 0 | G22: =(g_BC/2*g_cos-g_AC)*G11*g_BC-(g_yB-g_BC/2*g_sin-g_yA)*G10*g_BC -> -471.61464 | H22: N.mm
A23: 17 | B23: Vertical force on rafter at B (up +) | C23: VB | D23: =-(D20+D21+D22)/(0-g_AC) -> 94.316028 | E23: =-(E20+E21+E22)/(0-g_AC) -> -539.59103 | F23: =-(F20+F21+F22)/(0-g_AC) -> 300.99697 | G23: =-(G20+G21+G22)/(0-g_AC) -> -1.6826473 | H23: N | I23: moment equilibrium about C
A24: 18 | B24: Force on rafter at C, x | C24: Cx | D24: =-(2*D6+D8*g_Lm+D10*g_BC) -> 0 | E24: =-(2*E6+E8*g_Lm+E10*g_BC) -> -186.82517 | F24: =-(2*F6+F8*g_Lm+F10*g_BC) -> 104.21562 | G24: =-(2*G6+G8*g_Lm+G10*g_BC) -> -18.880962 | H24: N | I24: sum Fx = 0
A25: 19 | B25: Force on rafter at C, y | C25: Cy | D25: =-(2*D7+D9*g_Lm+D11*g_BC+D23) -> 94.493587 | E25: =-(2*E7+E9*g_Lm+E11*g_BC+E23) -> -507.60459 | F25: =-(2*F7+F9*g_Lm+F11*g_BC+F23) -> 283.15416 | G25: =-(2*G7+G9*g_Lm+G11*g_BC+G23) -> 1.6826473 | H25: N | I25: sum Fy = 0
A26: 20 | B26: Axial force in vertical member (tension +) | C26: NAB | D26: =-D23 -> -94.316028 | E26: =-E23 -> 539.59103 | F26: =-F23 -> -300.99697 | G26: =-G23 -> 1.6826473 | H26: N | I26: joint B
A27: 21 | B27: Point load per bolt: component normal to rafter | C27: Fn | D27: =D6*g_sin+D7*g_cos -> 0 | E27: =E6*g_sin+E7*g_cos -> 531.86518 | F27: =F6*g_sin+F7*g_cos -> -296.68731 | G27: =G6*g_sin+G7*g_cos -> 0 | H27: N | I27: n=(sin,cos)
A28: 22 | B28: Point load per bolt: component along rafter (B->C) | C28: Ft | D28: =D6*g_cos-D7*g_sin -> 0 | E28: =E6*g_cos-E7*g_sin -> 0 | F28: =F6*g_cos-F7*g_sin -> 0 | G28: =G6*g_cos-G7*g_sin -> 0 | H28: N | I28: d=(cos,-sin)
A29: 23 | B29: Module UDL, normal component | C29: qnm | D29: =D8*g_sin+D9*g_cos -> -0.12391252 | E29: =E8*g_sin+E9*g_cos -> 0 | F29: =F8*g_sin+F9*g_cos -> 0 | G29: =G8*g_sin+G9*g_cos -> 0.0022106642 | H29: N/mm
A30: 24 | B30: Module UDL, tangential component | C30: qtm | D30: =D8*g_cos-D9*g_sin -> 0.022106642 | E30: =E8*g_cos-E9*g_sin -> 0 | F30: =F8*g_cos-F9*g_sin -> 0 | G30: =G8*g_cos-G9*g_sin -> 0.012391252 | H30: N/mm
A31: 25 | B31: Rafter UDL, normal component | C31: qnr | D31: =D10*g_sin+D11*g_cos -> -0.038913189 | E31: =E10*g_sin+E11*g_cos -> 0 | F31: =F10*g_sin+F11*g_cos -> 0 | G31: =G10*g_sin+G11*g_cos -> 0.00069423163 | H31: N/mm
A32: 26 | B32: Rafter UDL, tangential component | C32: qtr | D32: =D10*g_cos-D11*g_sin -> 0.0069423163 | E32: =E10*g_cos-E11*g_sin -> 0 | F32: =F10*g_cos-F11*g_sin -> 0 | G32: =G10*g_cos-G11*g_sin -> 0.0038913189 | H32: N/mm
A33: 27 | B33: Total distributed normal load (deflection) | C33: qn | D33: =D29+D31 -> -0.16282571 | E33: =E29+E31 -> 0 | F33: =F29+F31 -> 0 | G33: =G29+G31 -> 0.0029048958 | H33: N/mm
A34: 28 | B34: Axial in rafter, at B (tension +) | C34: N_0 | D34: =D23*g_sin-D28*0-D30*MAX(0,MIN(0,g_sb)-g_sa)-D32*MAX(0,MIN(0,g_BC)) -> 16.56492 | E34: =E23*g_sin-E28*0-E30*MAX(0,MIN(0,g_sb)-g_sa)-E32*MAX(0,MIN(0,g_BC)) -> -94.769492 | F34: =F23*g_sin-F28*0-F30*MAX(0,MIN(0,g_sb)-g_sa)-F32*MAX(0,MIN(0,g_BC)) -> 52.864723 | G34: =G23*g_sin-G28*0-G30*MAX(0,MIN(0,g_sb)-g_sa)-G32*MAX(0,MIN(0,g_BC)) -> -0.29552683 | H34: N | I34: piecewise linear
A35: 29 | B35: Axial in rafter, start of module contact (tension +) | C35: N_a | D35: =D23*g_sin-D28*0-D30*MAX(0,MIN(g_sa,g_sb)-g_sa)-D32*MAX(0,MIN(g_sa,g_BC)) -> 16.450134 | E35: =E23*g_sin-E28*0-E30*MAX(0,MIN(g_sa,g_sb)-g_sa)-E32*MAX(0,MIN(g_sa,g_BC)) -> -94.769492 | F35: =F23*g_sin-F28*0-F30*MAX(0,MIN(g_sa,g_sb)-g_sa)-F32*MAX(0,MIN(g_sa,g_BC)) -> 52.864723 | G35: =G23*g_sin-G28*0-G30*MAX(0,MIN(g_sa,g_sb)-g_sa)-G32*MAX(0,MIN(g_sa,g_BC)) -> -0.3598669 | H35: N | I35: piecewise linear
A36: 30 | B36: Axial in rafter, just before module bolt 1 (tension +) | C36: N_1m | D36: =D23*g_sin-D28*0-D30*MAX(0,MIN(g_s1,g_sb)-g_sa)-D32*MAX(0,MIN(g_s1,g_BC)) -> 15.782131 | E36: =E23*g_sin-E28*0-E30*MAX(0,MIN(g_s1,g_sb)-g_sa)-E32*MAX(0,MIN(g_s1,g_BC)) -> -94.769492 | F36: =F23*g_sin-F28*0-F30*MAX(0,MIN(g_s1,g_sb)-g_sa)-F32*MAX(0,MIN(g_s1,g_BC)) -> 52.864723 | G36: =G23*g_sin-G28*0-G30*MAX(0,MIN(g_s1,g_sb)-g_sa)-G32*MAX(0,MIN(g_s1,g_BC)) -> -0.7342967 | H36: N | I36: piecewise linear
A37: 31 | B37: Axial in rafter, just after module bolt 1 (tension +) | C37: N_1p | D37: =D23*g_sin-D28*1-D30*MAX(0,MIN(g_s1,g_sb)-g_sa)-D32*MAX(0,MIN(g_s1,g_BC)) -> 15.782131 | E37: =E23*g_sin-E28*1-E30*MAX(0,MIN(g_s1,g_sb)-g_sa)-E32*MAX(0,MIN(g_s1,g_BC)) -> -94.769492 | F37: =F23*g_sin-F28*1-F30*MAX(0,MIN(g_s1,g_sb)-g_sa)-F32*MAX(0,MIN(g_s1,g_BC)) -> 52.864723 | G37: =G23*g_sin-G28*1-G30*MAX(0,MIN(g_s1,g_sb)-g_sa)-G32*MAX(0,MIN(g_s1,g_BC)) -> -0.7342967 | H37: N | I37: piecewise linear
A38: 32 | B38: Axial in rafter, just before module bolt 2 (tension +) | C38: N_2m | D38: =D23*g_sin-D28*1-D30*MAX(0,MIN(g_s2,g_sb)-g_sa)-D32*MAX(0,MIN(g_s2,g_BC)) -> -15.823383 | E38: =E23*g_sin-E28*1-E30*MAX(0,MIN(g_s2,g_sb)-g_sa)-E32*MAX(0,MIN(g_s2,g_BC)) -> -94.769492 | F38: =F23*g_sin-F28*1-F30*MAX(0,MIN(g_s2,g_sb)-g_sa)-F32*MAX(0,MIN(g_s2,g_BC)) -> 52.864723 | G38: =G23*g_sin-G28*1-G30*MAX(0,MIN(g_s2,g_sb)-g_sa)-G32*MAX(0,MIN(g_s2,g_BC)) -> -18.449873 | H38: N | I38: piecewise linear
A39: 33 | B39: Axial in rafter, just after module bolt 2 (tension +) | C39: N_2p | D39: =D23*g_sin-D28*2-D30*MAX(0,MIN(g_s2,g_sb)-g_sa)-D32*MAX(0,MIN(g_s2,g_BC)) -> -15.823383 | E39: =E23*g_sin-E28*2-E30*MAX(0,MIN(g_s2,g_sb)-g_sa)-E32*MAX(0,MIN(g_s2,g_BC)) -> -94.769492 | F39: =F23*g_sin-F28*2-F30*MAX(0,MIN(g_s2,g_sb)-g_sa)-F32*MAX(0,MIN(g_s2,g_BC)) -> 52.864723 | G39: =G23*g_sin-G28*2-G30*MAX(0,MIN(g_s2,g_sb)-g_sa)-G32*MAX(0,MIN(g_s2,g_BC)) -> -18.449873 | H39: N | I39: piecewise linear
A40: 34 | B40: Axial in rafter, end of module contact (tension +) | C40: N_b | D40: =D23*g_sin-D28*2-D30*MAX(0,MIN(g_sb,g_sb)-g_sa)-D32*MAX(0,MIN(g_sb,g_BC)) -> -16.491385 | E40: =E23*g_sin-E28*2-E30*MAX(0,MIN(g_sb,g_sb)-g_sa)-E32*MAX(0,MIN(g_sb,g_BC)) -> -94.769492 | F40: =F23*g_sin-F28*2-F30*MAX(0,MIN(g_sb,g_sb)-g_sa)-F32*MAX(0,MIN(g_sb,g_BC)) -> 52.864723 | G40: =G23*g_sin-G28*2-G30*MAX(0,MIN(g_sb,g_sb)-g_sa)-G32*MAX(0,MIN(g_sb,g_BC)) -> -18.824303 | H40: N | I40: piecewise linear
A41: 35 | B41: Axial in rafter, at C (tension +) | C41: N_L | D41: =D23*g_sin-D28*2-D30*MAX(0,MIN(g_BC,g_sb)-g_sa)-D32*MAX(0,MIN(g_BC,g_BC)) -> -16.596105 | E41: =E23*g_sin-E28*2-E30*MAX(0,MIN(g_BC,g_sb)-g_sa)-E32*MAX(0,MIN(g_BC,g_BC)) -> -94.769492 | F41: =F23*g_sin-F28*2-F30*MAX(0,MIN(g_BC,g_sb)-g_sa)-F32*MAX(0,MIN(g_BC,g_BC)) -> 52.864723 | G41: =G23*g_sin-G28*2-G30*MAX(0,MIN(g_BC,g_sb)-g_sa)-G32*MAX(0,MIN(g_BC,g_BC)) -> -18.883 | H41: N | I41: piecewise linear
...

Sheet Combos
A1: 7 LOAD COMBINATIONS (IS 800:2007 Table 4, limit state) AND ENVELOPES
A2: U = strength combinations C1-C6 (factored). S = service combinations (unfactored, deflection). 0.9DL when dead load is stabilising (Table 4 note).
A4: # | B4: Quantity | C4: Key | D4: C1 | E4: C2 | F4: C3 | G4: C4 | H4: C5 | I4: C6 | J4: S1 | K4: S2 | L4: max U | M4: min U | N4: abs max U | O4: Unit
B5: Combination | D5: 1.5DL + 1.5WL(down) | E5: 0.9DL + 1.5WL(up) | F5: 1.5DL + 1.5EQ(+x) | G5: 1.5DL - 1.5EQ(+x) | H5: 0.9DL + 1.5EQ(+x) | I5: 0.9DL - 1.5EQ(+x) | J5: DL + WL(down) [service] | K5: DL + WL(up) [service]
B6: Factor on DL dead | C6: DL | D6: 1.5 | E6: 0.9 | F6: 1.5 | G6: 1.5 | H6: 0.9 | I6: 0.9 | J6: 1 | K6: 1
B7: Factor on WL uplift | C7: WLU | D7: 0 | E7: 1.5 | F7: 0 | G7: 0 | H7: 0 | I7: 0 | J7: 0 | K7: 1
B8: Factor on WL downward | C8: WLD | D8: 1.5 | E8: 0 | F8: 0 | G8: 0 | H8: 0 | I8: 0 | J8: 1 | K8: 0
B9: Factor on EQ +x | C9: EQX | D9: 0 | E9: 0 | F9: 1.5 | G9: -1.5 | H9: 1.5 | I9: -1.5 | J9: 0 | K9: 0
A10: 1 | B10: Vertical force on rafter at B (up +) | C10: VB | D10: =D$6*Analysis!$D$23+D$7*Analysis!$E$23+D$8*Analysis!$F$23+D$9*Analysis!$G$23 -> 592.9695 | E10: =E$6*Analysis!$D$23+E$7*Analysis!$E$23+E$8*Analysis!$F$23+E$9*Analysis!$G$23 -> -724.50211 | F10: =F$6*Analysis!$D$23+F$7*Analysis!$E$23+F$8*Analysis!$F$23+F$9*Analysis!$G$23 -> 138.95007 | G10: =G$6*Analysis!$D$23+G$7*Analysis!$E$23+G$8*Analysis!$F$23+G$9*Analysis!$G$23 -> 143.99801 | H10: =H$6*Analysis!$D$23+H$7*Analysis!$E$23+H$8*Analysis!$F$23+H$9*Analysis!$G$23 -> 82.360454 | I10: =I$6*Analysis!$D$23+I$7*Analysis!$E$23+I$8*Analysis!$F$23+I$9*Analysis!$G$23 -> 87.408396 | J10: =J$6*Analysis!$D$23+J$7*Analysis!$E$23+J$8*Analysis!$F$23+J$9*Analysis!$G$23 -> 395.313 | K10: =K$6*Analysis!$D$23+K$7*Analysis!$E$23+K$8*Analysis!$F$23+K$9*Analysis!$G$23 -> -445.275 | L10: =MAX(D10:I10) -> 592.9695 | M10: =MIN(D10:I10) -> -724.50211 | N10: =MAX(L10,-M10) -> 724.50211 | O10: N
A11: 2 | B11: Force on rafter at C, x | C11: Cx | D11: =D$6*Analysis!$D$24+D$7*Analysis!$E$24+D$8*Analysis!$F$24+D$9*Analysis!$G$24 -> 156.32342 | E11: =E$6*Analysis!$D$24+E$7*Analysis!$E$24+E$8*Analysis!$F$24+E$9*Analysis!$G$24 -> -280.23776 | F11: =F$6*Analysis!$D$24+F$7*Analysis!$E$24+F$8*Analysis!$F$24+F$9*Analysis!$G$24 -> -28.321442 | G11: =G$6*Analysis!$D$24+G$7*Analysis!$E$24+G$8*Analysis!$F$24+G$9*Analysis!$G$24 -> 28.321442 | H11: =H$6*Analysis!$D$24+H$7*Analysis!$E$24+H$8*Analysis!$F$24+H$9*Analysis!$G$24 -> -28.321442 | I11: =I$6*Analysis!$D$24+I$7*Analysis!$E$24+I$8*Analysis!$F$24+I$9*Analysis!$G$24 -> 28.321442 | J11: =J$6*Analysis!$D$24+J$7*Analysis!$E$24+J$8*Analysis!$F$24+J$9*Analysis!$G$24 -> 104.21562 | K11: =K$6*Analysis!$D$24+K$7*Analysis!$E$24+K$8*Analysis!$F$24+K$9*Analysis!$G$24 -> -186.82517 | L11: =MAX(D11:I11) -> 156.32342 | M11: =MIN(D11:I11) -> -280.23776 | N11: =MAX(L11,-M11) -> 280.23776 | O11: N
A12: 3 | B12: Force on rafter at C, y | C12: Cy | D12: =D$6*Analysis!$D$25+D$7*Analysis!$E$25+D$8*Analysis!$F$25+D$9*Analysis!$G$25 -> 566.47162 | E12: =E$6*Analysis!$D$25+E$7*Analysis!$E$25+E$8*Analysis!$F$25+E$9*Analysis!$G$25 -> -676.36265 | F12: =F$6*Analysis!$D$25+F$7*Analysis!$E$25+F$8*Analysis!$F$25+F$9*Analysis!$G$25 -> 144.26435 | G12: =G$6*Analysis!$D$25+G$7*Analysis!$E$25+G$8*Analysis!$F$25+G$9*Analysis!$G$25 -> 139.21641 | H12: =H$6*Analysis!$D$25+H$7*Analysis!$E$25+H$8*Analysis!$F$25+H$9*Analysis!$G$25 -> 87.568199 | I12: =I$6*Analysis!$D$25+I$7*Analysis!$E$25+I$8*Analysis!$F$25+I$9*Analysis!$G$25 -> 82.520258 | J12: =J$6*Analysis!$D$25+J$7*Analysis!$E$25+J$8*Analysis!$F$25+J$9*Analysis!$G$25 -> 377.64775 | K12: =K$6*Analysis!$D$25+K$7*Analysis!$E$25+K$8*Analysis!$F$25+K$9*Analysis!$G$25 -> -413.111 | L12: =MAX(D12:I12) -> 566.47162 | M12: =MIN(D12:I12) -> -676.36265 | N12: =MAX(L12,-M12) -> 676.36265 | O12: N
A13: 4 | B13: Axial force in vertical member (tension +) | C13: NAB | D13: =D$6*Analysis!$D$26+D$7*Analysis!$E$26+D$8*Analysis!$F$26+D$9*Analysis!$G$26 -> -592.9695 | E13: =E$6*Analysis!$D$26+E$7*Analysis!$E$26+E$8*Analysis!$F$26+E$9*Analysis!$G$26 -> 724.50211 | F13: =F$6*Analysis!$D$26+F$7*Analysis!$E$26+F$8*Analysis!$F$26+F$9*Analysis!$G$26 -> -138.95007 | G13: =G$6*Analysis!$D$26+G$7*Analysis!$E$26+G$8*Analysis!$F$26+G$9*Analysis!$G$26 -> -143.99801 | H13: =H$6*Analysis!$D$26+H$7*Analysis!$E$26+H$8*Analysis!$F$26+H$9*Analysis!$G$26 -> -82.360454 | I13: =I$6*Analysis!$D$26+I$7*Analysis!$E$26+I$8*Analysis!$F$26+I$9*Analysis!$G$26 -> -87.408396 | J13: =J$6*Analysis!$D$26+J$7*Analysis!$E$26+J$8*Analysis!$F$26+J$9*Analysis!$G$26 -> -395.313 | K13: =K$6*Analysis!$D$26+K$7*Analysis!$E$26+K$8*Analysis!$F$26+K$9*Analysis!$G$26 -> 445.275 | L13: =MAX(D13:I13) -> 724.50211 | M13: =MIN(D13:I13) -> -592.9695 | N13: =MAX(L13,-M13) -> 724.50211 | O13: N
A14: 5 | B14: Point load per bolt: component normal to rafter | C14: Fn | D14: =D$6*Analysis!$D$27+D$7*Analysis!$E$27+D$8*Analysis!$F$27+D$9*Analysis!$G$27 -> -445.03096 | E14: =E$6*Analysis!$D$27+E$7*Analysis!$E$27+E$8*Analysis!$F$27+E$9*Analysis!$G$27 -> 797.79778 | F14: =F$6*Analysis!$D$27+F$7*Analysis!$E$27+F$8*Analysis!$F$27+F$9*Analysis!$G$27 -> 0 | G14: =G$6*Analysis!$D$27+G$7*Analysis!$E$27+G$8*Analysis!$F$27+G$9*Analysis!$G$27 -> 0 | H14: =H$6*Analysis!$D$27+H$7*Analysis!$E$27+H$8*Analysis!$F$27+H$9*Analysis!$G$27 -> 0 | I14: =I$6*Analysis!$D$27+I$7*Analysis!$E$27+I$8*Analysis!$F$27+I$9*Analysis!$G$27 -> 0 | J14: =J$6*Analysis!$D$27+J$7*Analysis!$E$27+J$8*Analysis!$F$27+J$9*Analysis!$G$27 -> -296.68731 | K14: =K$6*Analysis!$D$27+K$7*Analysis!$E$27+K$8*Analysis!$F$27+K$9*Analysis!$G$27 -> 531.86518 | L14: =MAX(D14:I14) -> 797.79778 | M14: =MIN(D14:I14) -> -445.03096 | N14: =MAX(L14,-M14) -> 797.79778 | O14: N
A15: 6 | B15: Point load per bolt: component along rafter (B->C) | C15: Ft | D15: =D$6*Analysis!$D$28+D$7*Analysis!$E$28+D$8*Analysis!$F$28+D$9*Analysis!$G$28 -> 0 | E15: =E$6*Analysis!$D$28+E$7*Analysis!$E$28+E$8*Analysis!$F$28+E$9*Analysis!$G$28 -> 0 | F15: =F$6*Analysis!$D$28+F$7*Analysis!$E$28+F$8*Analysis!$F$28+F$9*Analysis!$G$28 -> 0 | G15: =G$6*Analysis!$D$28+G$7*Analysis!$E$28+G$8*Analysis!$F$28+G$9*Analysis!$G$28 -> 0 | H15: =H$6*Analysis!$D$28+H$7*Analysis!$E$28+H$8*Analysis!$F$28+H$9*Analysis!$G$28 -> 0 | I15: =I$6*Analysis!$D$28+I$7*Analysis!$E$28+I$8*Analysis!$F$28+I$9*Analysis!$G$28 -> 0 | J15: =J$6*Analysis!$D$28+J$7*Analysis!$E$28+J$8*Analysis!$F$28+J$9*Analysis!$G$28 -> 0 | K15: =K$6*Analysis!$D$28+K$7*Analysis!$E$28+K$8*Analysis!$F$28+K$9*Analysis!$G$28 -> 0 | L15: =MAX(D15:I15) -> 0 | M15: =MIN(D15:I15) -> 0 | N15: =MAX(L15,-M15) -> 0 | O15: N
A16: 7 | B16: Module UDL, normal component | C16: qnm | D16: =D$6*Analysis!$D$29+D$7*Analysis!$E$29+D$8*Analysis!$F$29+D$9*Analysis!$G$29 -> -0.18586879 | E16: =E$6*Analysis!$D$29+E$7*Analysis!$E$29+E$8*Analysis!$F$29+E$9*Analysis!$G$29 -> -0.11152127 | F16: =F$6*Analysis!$D$29+F$7*Analysis!$E$29+F$8*Analysis!$F$29+F$9*Analysis!$G$29 -> -0.18255279 | G16: =G$6*Analysis!$D$29+G$7*Analysis!$E$29+G$8*Analysis!$F$29+G$9*Analysis!$G$29 -> -0.18918478 | H16: =H$6*Analysis!$D$29+H$7*Analysis!$E$29+H$8*Analysis!$F$29+H$9*Analysis!$G$29 -> -0.10820527 | I16: =I$6*Analysis!$D$29+I$7*Analysis!$E$29+I$8*Analysis!$F$29+I$9*Analysis!$G$29 -> -0.11483727 | J16: =J$6*Analysis!$D$29+J$7*Analysis!$E$29+J$8*Analysis!$F$29+J$9*Analysis!$G$29 -> -0.12391252 | K16: =K$6*Analysis!$D$29+K$7*Analysis!$E$29+K$8*Analysis!$F$29+K$9*Analysis!$G$29 -> -0.12391252 | L16: =MAX(D16:I16) -> -0.10820527 | M16: =MIN(D16:I16) -> -0.18918478 | N16: =MAX(L16,-M16) -> 0.18918478 | O16: N/mm
A17: 8 | B17: Rafter UDL, normal component | C17: qnr | D17: =D$6*Analysis!$D$31+D$7*Analysis!$E$31+D$8*Analysis!$F$31+D$9*Analysis!$G$31 -> -0.058369783 | E17: =E$6*Analysis!$D$31+E$7*Analysis!$E$31+E$8*Analysis!$F$31+E$9*Analysis!$G$31 -> -0.03502187 | F17: =F$6*Analysis!$D$31+F$7*Analysis!$E$31+F$8*Analysis!$F$31+F$9*Analysis!$G$31 -> -0.057328436 | G17: =G$6*Analysis!$D$31+G$7*Analysis!$E$31+G$8*Analysis!$F$31+G$9*Analysis!$G$31 -> -0.059411131 | H17: =H$6*Analysis!$D$31+H$7*Analysis!$E$31+H$8*Analysis!$F$31+H$9*Analysis!$G$31 -> -0.033980522 | I17: =I$6*Analysis!$D$31+I$7*Analysis!$E$31+I$8*Analysis!$F$31+I$9*Analysis!$G$31 -> -0.036063217 | J17: =J$6*Analysis!$D$31+J$7*Analysis!$E$31+J$8*Analysis!$F$31+J$9*Analysis!$G$31 -> -0.038913189 | K17: =K$6*Analysis!$D$31+K$7*Analysis!$E$31+K$8*Analysis!$F$31+K$9*Analysis!$G$31 -> -0.038913189 | L17: =MAX(D17:I17) -> -0.033980522 | M17: =MIN(D17:I17) -> -0.059411131 | N17: =MAX(L17,-M17) -> 0.059411131 | O17: N/mm
A18: 9 | B18: Total distributed normal load (deflection) | C18: qn | D18: =D$6*Analysis!$D$33+D$7*Analysis!$E$33+D$8*Analysis!$F$33+D$9*Analysis!$G$33 -> -0.24423857 | E18: =E$6*Analysis!$D$33+E$7*Analysis!$E$33+E$8*Analysis!$F$33+E$9*Analysis!$G$33 -> -0.14654314 | F18: =F$6*Analysis!$D$33+F$7*Analysis!$E$33+F$8*Analysis!$F$33+F$9*Analysis!$G$33 -> -0.23988122 | G18: =G$6*Analysis!$D$33+G$7*Analysis!$E$33+G$8*Analysis!$F$33+G$9*Analysis!$G$33 -> -0.24859591 | H18: =H$6*Analysis!$D$33+H$7*Analysis!$E$33+H$8*Analysis!$F$33+H$9*Analysis!$G$33 -> -0.1421858 | I18: =I$6*Analysis!$D$33+I$7*Analysis!$E$33+I$8*Analysis!$F$33+I$9*Analysis!$G$33 -> -0.15090048 | J18: =J$6*Analysis!$D$33+J$7*Analysis!$E$33+J$8*Analysis!$F$33+J$9*Analysis!$G$33 -> -0.16282571 | K18: =K$6*Analysis!$D$33+K$7*Analysis!$E$33+K$8*Analysis!$F$33+K$9*Analysis!$G$33 -> -0.16282571 | L18: =MAX(D18:I18) -> -0.1421858 | M18: =MIN(D18:I18) -> -0.24859591 | N18: =MAX(L18,-M18) -> 0.24859591 | O18: N/mm
A19: 10 | B19: Axial in rafter, at B (tension +) | C19: N_0 | D19: =D$6*Analysis!$D$34+D$7*Analysis!$E$34+D$8*Analysis!$F$34+D$9*Analysis!$G$34 -> 104.14446 | E19: =E$6*Analysis!$D$34+E$7*Analysis!$E$34+E$8*Analysis!$F$34+E$9*Analysis!$G$34 -> -127.24581 | F19: =F$6*Analysis!$D$34+F$7*Analysis!$E$34+F$8*Analysis!$F$34+F$9*Analysis!$G$34 -> 24.404089 | G19: =G$6*Analysis!$D$34+G$7*Analysis!$E$34+G$8*Analysis!$F$34+G$9*Analysis!$G$34 -> 25.29067 | H19: =H$6*Analysis!$D$34+H$7*Analysis!$E$34+H$8*Analysis!$F$34+H$9*Analysis!$G$34 -> 14.465138 | I19: =I$6*Analysis!$D$34+I$7*Analysis!$E$34+I$8*Analysis!$F$34+I$9*Analysis!$G$34 -> 15.351718 | J19: =J$6*Analysis!$D$34+J$7*Analysis!$E$34+J$8*Analysis!$F$34+J$9*Analysis!$G$34 -> 69.429643 | K19: =K$6*Analysis!$D$34+K$7*Analysis!$E$34+K$8*Analysis!$F$34+K$9*Analysis!$G$34 -> -78.204572 | L19: =MAX(D19:I19) -> 104.14446 | M19: =MIN(D19:I19) -> -127.24581 | N19: =MAX(L19,-M19) -> 127.24581 | O19: N
A20: 11 | B20: Axial in rafter, start of module contact (tension +) | C20: N_a | D20: =D$6*Analysis!$D$35+D$7*Analysis!$E$35+D$8*Analysis!$F$35+D$9*Analysis!$G$35 -> 103.97229 | E20: =E$6*Analysis!$D$35+E$7*Analysis!$E$35+E$8*Analysis!$F$35+E$9*Analysis!$G$35 -> -127.34912 | F20: =F$6*Analysis!$D$35+F$7*Analysis!$E$35+F$8*Analysis!$F$35+F$9*Analysis!$G$35 -> 24.1354 | G20: =G$6*Analysis!$D$35+G$7*Analysis!$E$35+G$8*Analysis!$F$35+G$9*Analysis!$G$35 -> 25.215001 | H20: =H$6*Analysis!$D$35+H$7*Analysis!$E$35+H$8*Analysis!$F$35+H$9*Analysis!$G$35 -> 14.26532 | I20: =I$6*Analysis!$D$35+I$7*Analysis!$E$35+I$8*Analysis!$F$35+I$9*Analysis!$G$35 -> 15.344921 | J20: =J$6*Analysis!$D$35+J$7*Analysis!$E$35+J$8*Analysis!$F$35+J$9*Analysis!$G$35 -> 69.314857 | K20: =K$6*Analysis!$D$35+K$7*Analysis!$E$35+K$8*Analysis!$F$35+K$9*Analysis!$G$35 -> -78.319358 | L20: =MAX(D20:I20) -> 103.97229 | M20: =MIN(D20:I20) -> -127.34912 | N20: =MAX(L20,-M20) -> 127.34912 | O20: N
A21: 12 | B21: Axial in rafter, just before module bolt 1 (tension +) | C21: N_1m | D21: =D$6*Analysis!$D$36+D$7*Analysis!$E$36+D$8*Analysis!$F$36+D$9*Analysis!$G$36 -> 102.97028 | E21: =E$6*Analysis!$D$36+E$7*Analysis!$E$36+E$8*Analysis!$F$36+E$9*Analysis!$G$36 -> -127.95032 | F21: =F$6*Analysis!$D$36+F$7*Analysis!$E$36+F$8*Analysis!$F$36+F$9*Analysis!$G$36 -> 22.571752 | G21: =G$6*Analysis!$D$36+G$7*Analysis!$E$36+G$8*Analysis!$F$36+G$9*Analysis!$G$36 -> 24.774642 | H21: =H$6*Analysis!$D$36+H$7*Analysis!$E$36+H$8*Analysis!$F$36+H$9*Analysis!$G$36 -> 13.102473 | I21: =I$6*Analysis!$D$36+I$7*Analysis!$E$36+I$8*Analysis!$F$36+I$9*Analysis!$G$36 -> 15.305363 | J21: =J$6*Analysis!$D$36+J$7*Analysis!$E$36+J$8*Analysis!$F$36+J$9*Analysis!$G$36 -> 68.646854 | K21: =K$6*Analysis!$D$36+K$7*Analysis!$E$36+K$8*Analysis!$F$36+K$9*Analysis!$G$36 -> -78.987361 | L21: =MAX(D21:I21) -> 102.97028 | M21: =MIN(D21:I21) -> -127.95032 | N21: =MAX(L21,-M21) -> 127.95032 | O21: N
A22: 13 | B22: Axial in rafter, just after module bolt 1 (tension +) | C22: N_1p | D22: =D$6*Analysis!$D$37+D$7*Analysis!$E$37+D$8*Analysis!$F$37+D$9*Analysis!$G$37 -> 102.97028 | E22: =E$6*Analysis!$D$37+E$7*Analysis!$E$37+E$8*Analysis!$F$37+E$9*Analysis!$G$37 -> -127.95032 | F22: =F$6*Analysis!$D$37+F$7*Analysis!$E$37+F$8*Analysis!$F$37+F$9*Analysis!$G$37 -> 22.571752 | G22: =G$6*Analysis!$D$37+G$7*Analysis!$E$37+G$8*Analysis!$F$37+G$9*Analysis!$G$37 -> 24.774642 | H22: =H$6*Analysis!$D$37+H$7*Analysis!$E$37+H$8*Analysis!$F$37+H$9*Analysis!$G$37 -> 13.102473 | I22: =I$6*Analysis!$D$37+I$7*Analysis!$E$37+I$8*Analysis!$F$37+I$9*Analysis!$G$37 -> 15.305363 | J22: =J$6*Analysis!$D$37+J$7*Analysis!$E$37+J$8*Analysis!$F$37+J$9*Analysis!$G$37 -> 68.646854 | K22: =K$6*Analysis!$D$37+K$7*Analysis!$E$37+K$8*Analysis!$F$37+K$9*Analysis!$G$37 -> -78.987361 | L22: =MAX(D22:I22) -> 102.97028 | M22: =MIN(D22:I22) -> -127.95032 | N22: =MAX(L22,-M22) -> 127.95032 | O22: N
A23: 14 | B23: Axial in rafter, just before module bolt 2 (tension +) | C23: N_2m | D23: =D$6*Analysis!$D$38+D$7*Analysis!$E$38+D$8*Analysis!$F$38+D$9*Analysis!$G$38 -> 55.56201 | E23: =E$6*Analysis!$D$38+E$7*Analysis!$E$38+E$8*Analysis!$F$38+E$9*Analysis!$G$38 -> -156.39528 | F23: =F$6*Analysis!$D$38+F$7*Analysis!$E$38+F$8*Analysis!$F$38+F$9*Analysis!$G$38 -> -51.409884 | G23: =G$6*Analysis!$D$38+G$7*Analysis!$E$38+G$8*Analysis!$F$38+G$9*Analysis!$G$38 -> 3.9397351 | H23: =H$6*Analysis!$D$38+H$7*Analysis!$E$38+H$8*Analysis!$F$38+H$9*Analysis!$G$38 -> -41.915854 | I23: =I$6*Analysis!$D$38+I$7*Analysis!$E$38+I$8*Analysis!$F$38+I$9*Analysis!$G$38 -> 13.433765 | J23: =J$6*Analysis!$D$38+J$7*Analysis!$E$38+J$8*Analysis!$F$38+J$9*Analysis!$G$38 -> 37.04134 | K23: =K$6*Analysis!$D$38+K$7*Analysis!$E$38+K$8*Analysis!$F$38+K$9*Analysis!$G$38 -> -110.59288 | L23: =MAX(D23:I23) -> 55.56201 | M23: =MIN(D23:I23) -> -156.39528 | N23: =MAX(L23,-M23) -> 156.39528 | O23: N
A24: 15 | B24: Axial in rafter, just after module bolt 2 (tension +) | C24: N_2p | D24: =D$6*Analysis!$D$39+D$7*Analysis!$E$39+D$8*Analysis!$F$39+D$9*Analysis!$G$39 -> 55.56201 | E24: =E$6*Analysis!$D$39+E$7*Analysis!$E$39+E$8*Analysis!$F$39+E$9*Analysis!$G$39 -> -156.39528 | F24: =F$6*Analysis!$D$39+F$7*Analysis!$E$39+F$8*Analysis!$F$39+F$9*Analysis!$G$39 -> -51.409884 | G24: =G$6*Analysis!$D$39+G$7*Analysis!$E$39+G$8*Analysis!$F$39+G$9*Analysis!$G$39 -> 3.9397351 | H24: =H$6*Analysis!$D$39+H$7*Analysis!$E$39+H$8*Analysis!$F$39+H$9*Analysis!$G$39 -> -41.915854 | I24: =I$6*Analysis!$D$39+I$7*Analysis!$E$39+I$8*Analysis!$F$39+I$9*Analysis!$G$39 -> 13.433765 | J24: =J$6*Analysis!$D$39+J$7*Analysis!$E$39+J$8*Analysis!$F$39+J$9*Analysis!$G$39 -> 37.04134 | K24: =K$6*Analysis!$D$39+K$7*Analysis!$E$39+K$8*Analysis!$F$39+K$9*Analysis!$G$39 -> -110.59288 | L24: =MAX(D24:I24) -> 55.56201 | M24: =MIN(D24:I24) -> -156.39528 | N24: =MAX(L24,-M24) -> 156.39528 | O24: N
A25: 16 | B25: Axial in rafter, end of module contact (tension +) | C25: N_b | D25: =D$6*Analysis!$D$40+D$7*Analysis!$E$40+D$8*Analysis!$F$40+D$9*Analysis!$G$40 -> 54.560007 | E25: =E$6*Analysis!$D$40+E$7*Analysis!$E$40+E$8*Analysis!$F$40+E$9*Analysis!$G$40 -> -156.99648 | F25: =F$6*Analysis!$D$40+F$7*Analysis!$E$40+F$8*Analysis!$F$40+F$9*Analysis!$G$40 -> -52.973532 | G25: =G$6*Analysis!$D$40+G$7*Analysis!$E$40+G$8*Analysis!$F$40+G$9*Analysis!$G$40 -> 3.4993763 | H25: =H$6*Analysis!$D$40+H$7*Analysis!$E$40+H$8*Analysis!$F$40+H$9*Analysis!$G$40 -> -43.078701 | I25: =I$6*Analysis!$D$40+I$7*Analysis!$E$40+I$8*Analysis!$F$40+I$9*Analysis!$G$40 -> 13.394207 | J25: =J$6*Analysis!$D$40+J$7*Analysis!$E$40+J$8*Analysis!$F$40+J$9*Analysis!$G$40 -> 36.373338 | K25: =K$6*Analysis!$D$40+K$7*Analysis!$E$40+K$8*Analysis!$F$40+K$9*Analysis!$G$40 -> -111.26088 | L25: =MAX(D25:I25) -> 54.560007 | M25: =MIN(D25:I25) -> -156.99648 | N25: =MAX(L25,-M25) -> 156.99648 | O25: N
A26: 17 | B26: Axial in rafter, at C (tension +) | C26: N_L | D26: =D$6*Analysis!$D$41+D$7*Analysis!$E$41+D$8*Analysis!$F$41+D$9*Analysis!$G$41 -> 54.402927 | E26: =E$6*Analysis!$D$41+E$7*Analysis!$E$41+E$8*Analysis!$F$41+E$9*Analysis!$G$41 -> -157.09073 | F26: =F$6*Analysis!$D$41+F$7*Analysis!$E$41+F$8*Analysis!$F$41+F$9*Analysis!$G$41 -> -53.218658 | G26: =G$6*Analysis!$D$41+G$7*Analysis!$E$41+G$8*Analysis!$F$41+G$9*Analysis!$G$41 -> 3.4303432 | H26: =H$6*Analysis!$D$41+H$7*Analysis!$E$41+H$8*Analysis!$F$41+H$9*Analysis!$G$41 -> -43.260995 | I26: =I$6*Analysis!$D$41+I$7*Analysis!$E$41+I$8*Analysis!$F$41+I$9*Analysis!$G$41 -> 13.388006 | J26: =J$6*Analysis!$D$41+J$7*Analysis!$E$41+J$8*Analysis!$F$41+J$9*Analysis!$G$41 -> 36.268618 | K26: =K$6*Analysis!$D$41+K$7*Analysis!$E$41+K$8*Analysis!$F$41+K$9*Analysis!$G$41 -> -111.3656 | L26: =MAX(D26:I26) -> 54.402927 | M26: =MIN(D26:I26) -> -157.09073 | N26: =MAX(L26,-M26) -> 157.09073 | O26: N
A27: 18 | B27: Shear in rafter, at B | C27: V_0 | D27: =D$6*Analysis!$D$42+D$7*Analysis!$E$42+D$8*Analysis!$F$42+D$9*Analysis!$G$42 -> -583.75231 | E27: =E$6*Analysis!$D$42+E$7*Analysis!$E$42+E$8*Analysis!$F$42+E$9*Analysis!$G$42 -> 713.24036 | F27: =F$6*Analysis!$D$42+F$7*Analysis!$E$42+F$8*Analysis!$F$42+F$9*Analysis!$G$42 -> -136.79021 | G27: =G$6*Analysis!$D$42+G$7*Analysis!$E$42+G$8*Analysis!$F$42+G$9*Analysis!$G$42 -> -141.75969 | H27: =H$6*Analysis!$D$42+H$7*Analysis!$E$42+H$8*Analysis!$F$42+H$9*Analysis!$G$42 -> -81.080233 | I27: =I$6*Analysis!$D$42+I$7*Analysis!$E$42+I$8*Analysis!$F$42+I$9*Analysis!$G$42 -> -86.049709 | J27: =J$6*Analysis!$D$42+J$7*Analysis!$E$42+J$8*Analysis!$F$42+J$9*Analysis!$G$42 -> -389.16821 | K27: =K$6*Analysis!$D$42+K$7*Analysis!$E$42+K$8*Analysis!$F$42+K$9*Analysis!$G$42 -> 438.35359 | L27: =MAX(D27:I27) -> 713.24036 | M27: =MIN(D27:I27) -> -583.75231 | N27: =MAX(L27,-M27) -> 713.24036 | O27: N
